2022-05-15 16:51:56,957 Task exception was never retrieved
future: <Task finished name='Task-7' coro=<background_on_start() done, defined at /Users/yustas/PycharmProjects/TikTok_mastermind/handlers/personal_actions.py:87> exception=KeyboardInterrupt()>
Traceback (most recent call last):
  File "/Users/yustas/Library/Caches/pypoetry/virtualenvs/repl-python3-tiktokmastermind-FiszdxE2-py3.10/lib/python3.10/site-packages/aiogram/utils/executor.py", line 320, in start_polling
    loop.run_until_complete(self._startup_polling())
  File "/usr/local/Cellar/python@3.10/3.10.1/Frameworks/Python.framework/Versions/3.10/lib/python3.10/asyncio/base_events.py", line 628, in run_until_complete
    self.run_forever()
  File "/usr/local/Cellar/python@3.10/3.10.1/Frameworks/Python.framework/Versions/3.10/lib/python3.10/asyncio/base_events.py", line 595, in run_forever
    self._run_once()
  File "/usr/local/Cellar/python@3.10/3.10.1/Frameworks/Python.framework/Versions/3.10/lib/python3.10/asyncio/base_events.py", line 1881, in _run_once
    handle._run()
  File "/usr/local/Cellar/python@3.10/3.10.1/Frameworks/Python.framework/Versions/3.10/lib/python3.10/asyncio/events.py", line 80, in _run
    self._context.run(self._callback, *self._args)
  File "/Users/yustas/PycharmProjects/TikTok_mastermind/handlers/personal_actions.py", line 93, in background_on_start
    await broadcaster(**kwargs)
  File "/Users/yustas/PycharmProjects/TikTok_mastermind/handlers/personal_actions.py", line 68, in broadcaster
    news_text = regular_news()  # Getting a link from the register
  File "/Users/yustas/PycharmProjects/TikTok_mastermind/bot.py", line 65, in regular_news
    time.sleep(600)
KeyboardInterrupt
